File: Uni Exercises/OFZ12-HIIab_CeRu4Sn12_OFZ12-HIIc-2.dat
[Header]
TITLE, default name
FILEOPENTIME, 31176721.30, 12/27/2014, 7:08 PM
BYAPP, Resistivity, 2.0, 1.0
INFO, APPNAME, PPMS MultiVu Application, Release 1.5.0.19
INFO, , Sample1 Name
INFO, 1, Sample1 Cross Section
INFO, 1, Sample1 Length
INFO, Ohm-m, Sample1 Units
INFO, , Sample2 Name
INFO, 1, Sample2 Cross Section
INFO, 1, Sample2 Length
INFO, Ohm-m, Sample2 Units
INFO, , Sample3 Name
INFO, 1, Sample3 Cross Section
INFO, 1, Sample3 Length
INFO, Ohm-m, Sample3 Units
INFO, , Sample4 Name
INFO, 1, Sample4 Cross Section
INFO, 1, Sample4 Length
INFO, Ohm-m, Sample4 Units
FIELDGROUP, Resistivity,2,3,4,5,6,7,8,9,10,11,12,13,14,15,16,17,18,19,20,21,22,23,24,25,26,27,28,29,30,31,32,33,34,35,36,37,38,39,40,41
STARTUPGROUP, Resistivity
STARTUPAXIS, X, 2, LINEAR, AUTO
STARTUPAXIS, Y1, 7, LINEAR, AUTO
STARTUPAXIS, Y2, 9, LINEAR, AUTO
STARTUPAXIS, Y3, 11, LINEAR, AUTO
PLOT_APPEARANCE, ALL, HORZ_GRID_ON, VERT_GRID_ON, MARKERS_AND_LINES, ALL_LINES
DATATYPE, TIME, 2
DATATYPE, COMMENT, 1
[Data]
Comment,Time Stamp (sec),Status (code),Temperature (K),Magnetic Field (Oe),Sample Position (deg),Bridge 1 Resistivity (Ohm-m),Bridge 1 Excitation (uA),Bridge 2 Resistivity (Ohm-m),Bridge 2 Excitation (uA),Bridge 3 Resistivity (Ohm-m),Bridge 3 Excitation (uA),Bridge 4 Resistivity (Ohm-m),Bridge 4 Excitation (uA),Bridge 1 Std. Dev. (Ohm-m),Bridge 2 Std. Dev. (Ohm-m),Bridge 3 Std. Dev. (Ohm-m),Bridge 4 Std. Dev. (Ohm-m),Number of Readings,Bridge 1 Resistance (Ohms),Bridge 2 Resistance (Ohms),Bridge 3 Resistance (Ohms),Bridge 4 Resistance (Ohms),Signal 1 Vin (V),Signal 2 Vin (V),Digital Inputs (code),Drive 1 Iout (mA),Drive 1 Ipower (watts),Drive 2 Iout (mA),Drive 2 Ipower (watts),Pressure (),Map 20 (),Map 21 (),Map 22 (),Map 23 (),Map 24 (),Map 25 (),Map 26 (),Map 27 (),Map 28 (),Map 29 ()
,31176930.06,4374,299.934494018555,-1.28100001811981,,8.71271507814527e-006,199.804992675781,2.72252531722188e-005,199.804992675781,9.56728059798478e-006,199.804992675781,,,1.65841071873723e-007,1.66884575974801e-007,2.05773415791761e-007,,50,0.00871271507814527,0.0272252531722188,0.00956728059798479,
,31176988.30,4374,299.197402954102,-1.28100001811981,,8.70412354357541e-006,199.804992675781,2.71811502054334e-005,199.804992675781,9.51897738501429e-006,199.804992675781,,,2.0306040423502e-007,1.58887279168919e-007,2.11969206541608e-007,,50,0.00870412354357541,0.0271811502054334,0.0095189773850143,
,31177046.73,4370,295.534103393555,-1.28100001811981,,8.67567617446185e-006,199.804992675781,2.71170005202293e-005,199.804992675781,9.49663957580923e-006,199.804992675781,,,1.1748575635774e-007,1.36502570622816e-007,1.25714228930063e-007,,50,0.00867567617446184,0.0271170005202293,0.00949663957580924,
,31177123.02,4374,293.90315246582,-1.28100001811981,,8.65582035854459e-006,199.804992675781,2.69904191419482e-005,199.804992675781,9.47181973606347e-006,199.804992675781,,,1.10187007023037e-007,1.32878142056258e-007,1.092813939822e-007,,50,0.00865582035854459,0.0269904191419482,0.00947181973606348,
,31177179.27,4370,291.722305297852,-1.28100001811981,,8.65524761378766e-006,199.804992675781,2.69566258043051e-005,199.804992675781,9.47964757680892e-006,199.804992675781,,,1.07688012838896e-007,1.01393264829373e-007,1.09841541053442e-007,,50,0.00865524761378765,0.0269566258043051,0.00947964757680893,
,31177235.30,4370,289.800903320313,-1.28100001811981,,8.62088164314628e-006,199.804992675781,2.68825481086969e-005,199.804992675781,9.40747912973165e-006,199.804992675781,,,1.02492133984589e-007,1.32588737469476e-007,1.14094556985208e-007,,50,0.00862088164314628,0.0268825481086969,0.00940747912973166,
,31177292.80,4370,287.874664306641,-1.28100001811981,,8.59224347397685e-006,199.804992675781,2.6840736232698e-005,199.804992675781,9.37826819717883e-006,199.804992675781,,,1.10550697725116e-007,1.1011133510929e-007,1.0877662241597e-007,,50,0.00859224347397685,0.026840736232698,0.00937826819717884,
,31177347.86,4370,286.032989501953,-1.28100001811981,,8.54260376654566e-006,199.804992675781,2.68098069727421e-005,199.804992675781,9.37750443816184e-006,199.804992675781,,,1.78658597342853e-007,1.20010541749401e-007,1.30660939670811e-007,,50,0.00854260376654565,0.0268098069727421,0.00937750443816185,
,31177404.02,4370,284.144500732422,-1.28100001811981,,8.56074130162597e-006,199.804992675781,2.6741457208991e-005,199.804992675781,9.37845904380082e-006,199.804992675781,,,1.16106244279268e-007,1.14922082942226e-007,1.14125172046283e-007,,50,0.00856074130162597,0.0267414572089911,0.00937845904380083,
,31177462.48,4370,282.195205688477,-1.28100001811981,,8.50346483290196e-006,199.804992675781,2.66700526699424e-005,199.804992675781,9.30629059672355e-006,199.804992675781,,,1.06374157171683e-007,1.24767943027103e-007,1.13041865170732e-007,,50,0.00850346483290195,0.0266700526699424,0.00930629059672356,
,31177519.75,4370,280.286148071289,-1.28100001811981,,8.48971845582128e-006,199.804992675781,2.66267135739326e-005,199.804992675781,9.29540811106562e-006,199.804992675781,,,9.55297551637742e-008,1.20023049495551e-007,9.76656332404371e-008,,50,0.00848971845582128,0.0266267135739326,0.00929540811106563,
,31177577.19,4370,278.37744140625,-1.28100001811981,,8.46470780670644e-006,199.804992675781,2.65304892882705e-005,199.804992675781,9.227821752429e-006,199.804992675781,,,1.11473460342614e-007,1.26887251445921e-007,1.11727670416506e-007,,50,0.00846470780670643,0.0265304892882705,0.00922782175242901,
,31177634.39,4370,276.468399047852,-1.28100001811981,,8.42709613963962e-006,199.804992675781,2.64978418126702e-005,199.804992675781,9.22362143173813e-006,199.804992675781,,,1.2514176372329e-007,1.03824763022956e-007,1.10574641106294e-007,,50,0.00842709613963962,0.0264978418126702,0.00922362143173814,
,31177690.59,4370,274.595199584961,-1.28100001811981,,8.44389725476504e-006,199.804992675781,2.64342648908496e-005,199.804992675781,9.21102067455649e-006,199.804992675781,,,1.14269621237827e-007,1.27226598346149e-007,1.13035492279761e-007,,50,0.00844389725476503,0.0264342648908496,0.00921102067455649,
,31177747.91,4370,272.688491821289,-1.28100001811981,,8.4080039896071e-006,199.804992675781,2.6378324739635e-005,199.804992675781,9.17226359248161e-006,199.804992675781,,,1.2671925981462e-007,1.36236143710344e-007,1.08596619804025e-007,,50,0.00840800398960709,0.026378324739635,0.00917226359248161,
,31177805.16,4370,270.781295776367,-1.28100001811981,,8.3346899971366e-006,199.804992675781,2.63313581421971e-005,199.804992675781,9.16462672874331e-006,199.804992675781,,,1.03877009186605e-007,9.41657540326568e-008,1.15786643689338e-007,,50,0.00833468999713659,0.0263313581421971,0.00916462672874331,
,31177862.47,4370,268.867752075195,-1.28100001811981,,8.32056177780033e-006,199.804992675781,2.62538435310125e-005,199.804992675781,9.12816071882844e-006,199.804992675781,,,9.74990170923445e-008,1.13326502663529e-007,1.23558779924236e-007,,50,0.00832056177780032,0.0262538435310125,0.00912816071882844,
,31177918.81,4370,266.992050170898,-1.28100001811981,,8.34118137136103e-006,199.804992675781,2.62374241650105e-005,199.804992675781,9.10410454496741e-006,199.804992675781,,,1.04437732463009e-007,1.0088686773838e-007,1.0452421790758e-007,,50,0.00834118137136102,0.0262374241650105,0.00910410454496741,
,31177975.05,4370,265.120559692383,-1.28100001811981,,8.25278457254172e-006,199.804992675781,2.61740377917886e-005,199.804992675781,9.05981071293354e-006,199.804992675781,,,1.17183655517839e-007,1.01960746970263e-007,1.29227533432332e-007,,50,0.00825278457254171,0.0261740377917886,0.00905981071293354,
,31178032.30,4370,263.2060546875,-1.28100001811981,,8.26347619295121e-006,199.804992675781,2.60852587223053e-005,199.804992675781,9.04835544526577e-006,199.804992675781,,,1.12753151787607e-007,9.22803626522632e-008,1.11571058978597e-007,,50,0.0082634761929512,0.0260852587223053,0.00904835544526577,
,31178090.64,4370,261.260650634766,-1.28100001811981,,8.26901298016311e-006,199.804992675781,2.60608204826713e-005,199.804992675781,8.9861149713397e-006,199.804992675781,,,1.2501060590908e-007,1.07325089656238e-007,1.01163531090419e-007,,50,0.0082690129801631,0.0260608204826713,0.0089861149713397,
,31178149.11,4370,259.316650390625,-1.28100001811981,,8.19627172313631e-006,199.804992675781,2.60081260278821e-005,199.804992675781,8.99661559611559e-006,199.804992675781,,,1.12627622331178e-007,1.11754773468683e-007,1.15253531176671e-007,,50,0.00819627172313631,0.0260081260278821,0.00899661559611559,
,31178207.41,4370,257.362838745117,-1.28100001811981,,8.18004345521331e-006,199.804992675781,2.59915157780051e-005,199.804992675781,8.94964883103967e-006,199.804992675781,,,9.76177252396526e-008,1.12073255247554e-007,1.06459033601371e-007,,50,0.00818004345521331,0.0259915157780051,0.00894964883103967,
,31178265.55,4370,255.429100036621,-1.28100001811981,,8.15655992366374e-006,199.804992675781,2.59449307620525e-005,199.804992675781,8.90573687851429e-006,199.804992675781,,,1.31405771848449e-007,9.58612764975401e-008,1.10237095838628e-007,,50,0.00815655992366373,0.0259449307620525,0.00890573687851429,
,31178323.92,4370,253.48664855957,-1.28100001811981,,8.0817186459899e-006,199.804992675781,2.58792536333203e-005,199.804992675781,8.87251649051905e-006,199.804992675781,,,1.09626352494658e-007,9.37943640313272e-008,1.11980972941228e-007,,50,0.0080817186459899,0.0258792536333203,0.00887251649051905,
,31178381.22,4370,251.584548950195,-1.28100001811981,,8.06778132915497e-006,199.804992675781,2.5819495357573e-005,199.804992675781,8.82898636162281e-006,199.804992675781,,,1.30205535088013e-007,1.09892405427146e-007,1.16237260024223e-007,,50,0.00806778132915497,0.025819495357573,0.00882898636162281,
,31178438.61,4370,249.666648864746,-1.28100001811981,,8.04257969371975e-006,199.804992675781,2.57547730579972e-005,199.804992675781,8.82478602230549e-006,199.804992675781,,,1.18636865100872e-007,1.14765832726881e-007,1.10737174133157e-007,,50,0.00804257969371974,0.0257547730579972,0.00882478602230549,
,31178497.09,4370,247.715950012207,-1.28100001811981,,8.03570657968521e-006,199.804992675781,2.57270894944668e-005,199.804992675781,8.78240145742894e-006,199.804992675781,,,1.22551729468426e-007,1.00119155927081e-007,1.26225122234768e-007,,50,0.00803570657968521,0.0257270894944668,0.00878240145742893,
,31178555.48,4370,245.771697998047,-1.28100001811981,,7.9992404859513e-006,199.804992675781,2.56621763110161e-005,199.804992675781,8.75490874052048e-006,199.804992675781,,,1.07051836470056e-007,1.28053292587897e-007,1.11188573355079e-007,,50,0.0079992404859513,0.0256621763110161,0.00875490874052048,
,31178614.03,4370,243.821502685547,-1.28100001811981,,7.97155676409602e-006,199.804992675781,2.56136823445558e-005,199.804992675781,8.73848956078292e-006,199.804992675781,,,1.2480817448569e-007,1.42723727258064e-007,9.83571418176493e-008,,50,0.00797155676409602,0.0256136823445559,0.00873848956078291,
,31178672.33,4370,241.874496459961,-1.28100001811981,,7.92726282961666e-006,199.804992675781,2.55852350965142e-005,199.804992675781,8.66899399086834e-006,199.804992675781,,,1.2415926337254e-007,9.98773000729362e-008,1.00259220552803e-007,,50,0.00792726282961667,0.0255852350965142,0.00866899399086833,
,31178730.86,4370,239.925750732422,-1.28100001811981,,7.89327873848378e-006,199.804992675781,2.55579333752393e-005,199.804992675781,8.65830233320594e-006,199.804992675781,,,1.15519759935298e-007,1.17992346281341e-007,1.00683026194838e-007,,50,0.00789327873848379,0.0255579333752394,0.00865830233320594,
,31178789.41,4370,237.972602844238,-1.28100001811981,,7.86654966883361e-006,199.804992675781,2.54930201917886e-005,199.804992675781,8.63157328218222e-006,199.804992675781,,,1.0659897902586e-007,1.12193416312664e-007,1.24099127948323e-007,,50,0.00786654966883361,0.0254930201917887,0.00863157328218222,
,31178847.88,4370,236.016304016113,-1.28100001811981,,7.81652812846005e-006,199.804992675781,2.54435716196894e-005,199.804992675781,8.59739834442735e-006,199.804992675781,,,1.15766898106715e-007,1.10381640735847e-007,1.31026939990923e-007,,50,0.00781652812846005,0.0254435716196895,0.00859739834442735,
,31178906.41,4370,234.070503234863,-1.28100001811981,,7.82111023552716e-006,199.804992675781,2.5383431315422e-005,199.804992675781,8.53859441354871e-006,199.804992675781,,,1.03771894693242e-007,1.43254405464757e-007,9.74674527458951e-008,,50,0.00782111023552716,0.0253834313154221,0.00853859441354871,
,31178964.89,4370,232.116851806641,-1.28100001811981,,7.77242510579527e-006,199.804992675781,2.53486838191747e-005,199.804992675781,8.4815089404583e-006,199.804992675781,,,1.1559843653044e-007,1.29376360815407e-007,1.10011971523503e-007,,50,0.00777242510579526,0.0253486838191748,0.0084815089404583,
,31179022.11,4370,230.216598510742,-1.28100001811981,,7.72698576562107e-006,199.804992675781,2.53076357766986e-005,199.804992675781,8.47979065030814e-006,199.804992675781,,,1.17415443573577e-007,9.22812881873123e-008,1.01660170754557e-007,,50,0.00772698576562107,0.0253076357766986,0.00847979065030813,
,31179079.38,4370,228.313697814941,-1.28100001811981,,7.67429137602449e-006,199.804992675781,2.52763246372342e-005,199.804992675781,8.43969698995353e-006,199.804992675781,,,1.04377366327277e-007,1.10052417580564e-007,1.00215806334508e-007,,50,0.00767429137602448,0.0252763246372342,0.00843969698995352,
,31179136.78,4370,226.394401550293,-1.28100001811981,,7.68288279883564e-006,199.804992675781,2.51978558301925e-005,199.804992675781,8.42652335762978e-006,199.804992675781,,,1.0579693459962e-007,1.01727646651586e-007,1.04642559752328e-007,,50,0.00768288279883564,0.0251978558301926,0.00842652335762978,
,31179195.19,4370,224.442947387695,-1.28100001811981,,7.64565313234926e-006,199.804992675781,2.51566166430711e-005,199.804992675781,8.3499637246132e-006,199.804992675781,,,1.10270010066382e-007,1.08222021783264e-007,1.33197851736068e-007,,50,0.00764565313234925,0.0251566166430712,0.00834996372461319,
,31179253.92,4370,222.488906860352,-1.28100001811981,,7.58054880425334e-006,199.804992675781,2.5143251940608e-005,199.804992675781,8.33602650091053e-006,199.804992675781,,,1.12031332046839e-007,1.15356634180327e-007,1.3388454350125e-007,,50,0.00758054880425334,0.025143251940608,0.00833602650091052,
,31179312.52,4370,220.53734588623,-1.28100001811981,,7.55572902970016e-006,199.804992675781,2.51056403294205e-005,199.804992675781,8.28848699107767e-006,199.804992675781,,,1.10326451419046e-007,9.53931936379759e-008,1.1424725933773e-007,,50,0.00755572902970016,0.0251056403294206,0.00828848699107766,
,31179371.16,4370,218.582000732422,-1.28100001811981,,7.52575431019068e-006,199.804992675781,2.50426356866956e-005,199.804992675781,8.2690129801631e-006,199.804992675781,,,8.83157392940949e-008,1.10778770538025e-007,1.10426270387788e-007,,50,0.00752575431019068,0.0250426356866956,0.0082690129801631,
,31179429.75,4370,216.634399414063,-1.28100001811981,,7.50895321369171e-006,199.804992675781,2.49971952661872e-005,199.804992675781,8.20429055020214e-006,199.804992675781,,,1.35661941857379e-007,1.05234790848989e-007,9.06658709443985e-008,,50,0.00750895321369171,0.0249971952661872,0.00820429055020213,
,31179487.03,4370,214.719146728516,-1.28100001811981,,7.48890646733344e-006,199.804992675781,2.49527104198933e-005,199.804992675781,8.17164285108448e-006,199.804992675781,,,1.10672944483213e-007,9.38604804263072e-008,1.14624483667595e-007,,50,0.00748890646733344,0.0249527104198933,0.00817164285108447,
,31179545.67,4370,212.764053344727,-1.28100001811981,,7.42151099257171e-006,199.804992675781,2.4924453869462e-005,199.804992675781,8.12353057786823e-006,199.804992675781,,,1.1666803696755e-007,9.9718698648576e-008,1.15747952485053e-007,,50,0.00742151099257171,0.024924453869462,0.00812353057786822,
,31179604.22,4370,210.818801879883,-1.28100001811981,,7.36480721272528e-006,199.804992675781,2.48759596049786e-005,199.804992675781,8.07942759245634e-006,199.804992675781,,,1.2143062082989e-007,1.12524814676981e-007,9.85933563556051e-008,,50,0.00736480721272528,0.0248759596049786,0.00807942759245634,
,31179661.58,4370,208.910949707031,-1.28100001811981,,7.35411556437611e-006,199.804992675781,2.48480850458145e-005,199.804992675781,8.06606313213706e-006,199.804992675781,,,9.96619603143592e-008,1.14743083056322e-007,1.00772835838779e-007,,50,0.00735411556437612,0.0248480850458145,0.00806606313213706,
,31179720.20,4370,206.947853088379,-1.28100001811981,,7.2819472104311e-006,199.804992675781,2.48232652246952e-005,199.804992675781,7.99255819059908e-006,199.804992675781,,,9.23099942917754e-008,9.47855474055483e-008,1.25716075362605e-007,,50,0.0072819472104311,0.0248232652246952,0.00799255819059908,
,31179778.89,4370,204.990699768066,-1.28100001811981,,7.25407261401415e-006,199.804992675781,2.47875630483031e-005,199.804992675781,7.97022032551467e-006,199.804992675781,,,1.20329937254854e-007,1.01222632431816e-007,9.83913619413825e-008,,50,0.00725407261401415,0.0247875630483031,0.00797022032551467,
,31179837.09,4370,203.05094909668,-1.28100001811981,,7.22505258396268e-006,199.804992675781,2.47507151216268e-005,199.804992675781,7.9041613265872e-006,199.804992675781,,,9.09840838899213e-008,1.11889554581213e-007,1.08775292312614e-007,,50,0.00722505258396268,0.0247507151216269,0.0079041613265872,
,31179895.30,4370,201.113998413086,-1.28100001811981,,7.19412322156131e-006,199.804992675781,2.47199768945575e-005,199.804992675781,7.84421178512275e-006,199.804992675781,,,1.14248665697996e-007,1.08627649471333e-007,9.08243746867341e-008,,50,0.00719412322156131,0.0247199768945575,0.00784421178512275,
,31179953.94,4370,199.156600952148,-1.28100001811981,,7.18476803041994e-006,199.804992675781,2.47612157836556e-005,199.804992675781,7.80049060471356e-006,199.804992675781,,,1.09722090196008e-007,1.16038745379385e-007,1.09293552332309e-007,,50,0.00718476803041995,0.0247612157836556,0.00780049060471356,
,31180012.58,4370,197.203353881836,-1.28100001811981,,7.09808951243758e-006,199.804992675781,2.46938206255436e-005,199.804992675781,7.78540777042508e-006,199.804992675781,,,1.21038375022458e-007,1.36144302027292e-007,9.49471948360636e-008,,50,0.00709808951243758,0.0246938206255436,0.00778540777042508,
,31180069.95,4370,195.293350219727,-1.28100001811981,,7.05532304011285e-006,199.804992675781,2.46785469353199e-005,199.804992675781,7.71419395692647e-006,199.804992675781,,,1.05523579300156e-007,8.59145075106849e-008,1.04471904036376e-007,,50,0.00705532304011285,0.0246785469353199,0.00771419395692647,
,31180128.56,4370,193.33740234375,-1.28100001811981,,6.98029079474509e-006,199.804992675781,2.46529635041952e-005,199.804992675781,7.69452909938991e-006,199.804992675781,,,1.0644283029325e-007,1.03858987753975e-007,1.24567661489261e-007,,50,0.00698029079474509,0.0246529635041952,0.00769452909938991,
,31180185.61,4370,191.435905456543,-1.28100001811981,,6.98773671872914e-006,199.804992675781,2.4624134413898e-005,199.804992675781,7.63553425669671e-006,199.804992675781,,,1.20809892832865e-007,1.13115733268922e-007,1.07307626016583e-007,,50,0.00698773671872914,0.024624134413898,0.0076355342566967,
,31180243.95,4370,189.498603820801,-1.28100001811981,,6.93637880496681e-006,199.804992675781,2.45817499235272e-005,199.804992675781,7.61644213460386e-006,199.804992675781,,,1.20762994187796e-007,1.19648459661684e-007,1.34880552798214e-007,,50,0.00693637880496681,0.0245817499235272,0.00761644213460386,
,31180301.39,4370,187.577346801758,-1.28100001811981,,6.91194081678986e-006,199.804992675781,2.45704855769873e-005,199.804992675781,7.5452283397317e-006,199.804992675781,,,1.09898803926614e-007,1.21120459777516e-007,1.03080037000973e-007,,50,0.00691194081678987,0.0245704855769873,0.00754522833973169,
,31180359.95,4370,185.626647949219,-1.28100001811981,,6.86287388205528e-006,199.804992675781,2.44927806779742e-005,199.804992675781,7.48546983115375e-006,199.804992675781,,,1.11109940805499e-007,9.18568749090676e-008,1.45113224682261e-007,,50,0.00686287388205528,0.0244927806779742,0.00748546983115375,
,31180417.19,4370,183.722900390625,-1.28100001811981,,6.79204189218581e-006,199.804992675781,2.44702519848943e-005,199.804992675781,7.43945761583746e-006,199.804992675781,,,1.1516002315316e-007,1.05403161062824e-007,1.10873468159836e-007,,50,0.00679204189218581,0.0244702519848943,0.00743945761583745,
,31180473.34,4370,181.846748352051,-1.28100001811981,,6.73228337429464e-006,199.804992675781,2.44775069877505e-005,199.804992675781,7.38619045354426e-006,199.804992675781,,,1.1625176568437e-007,9.13235846735005e-008,1.1161674802343e-007,,50,0.00673228337429464,0.0244775069877505,0.00738619045354426,
,31180531.84,4370,179.89624786377,-1.28100001811981,,6.73075601458549e-006,199.804992675781,2.44288221001625e-005,199.804992675781,7.35182456672191e-006,199.804992675781,,,1.06486431240277e-007,1.03379163009975e-007,9.85793950010124e-008,,50,0.0067307560145855,0.0244288221001625,0.00735182456672192,
,31180590.23,4370,177.94554901123,-1.28100001811981,,6.67252488434315e-006,199.804992675781,2.43999930098653e-005,199.804992675781,7.2882476169616e-006,199.804992675781,,,1.2325164037024e-007,1.10462186462734e-007,1.24483941381361e-007,,50,0.00667252488434315,0.0243999930098653,0.0072882476169616,
,31180648.67,4370,176.005897521973,-1.28100001811981,,6.53525207191705e-006,199.804992675781,2.4353408254683e-005,199.804992675781,7.25731831975281e-006,199.804992675781,,,6.45953558393544e-007,1.17381719069994e-007,8.78149112328447e-008,,50,0.00653525207191706,0.024353408254683,0.00725731831975281,
,31180705.86,4370,174.100944519043,-1.28100001811981,,6.55854453332722e-006,199.804992675781,2.43299249559641e-005,199.804992675781,7.19488685950637e-006,199.804992675781,,,9.73881238997738e-008,1.18838855614656e-007,1.09097289965918e-007,,50,0.00655854453332722,0.0243299249559641,0.00719488685950637,
,31180762.00,4370,172.229652404785,-1.28100001811981,,6.54327084310352e-006,199.804992675781,2.43039596825838e-005,199.804992675781,7.14352888055146e-006,199.804992675781,,,1.12078794807623e-007,1.1285296023762e-007,9.5831302587891e-008,,50,0.00654327084310353,0.0243039596825838,0.00714352888055146,
,31180818.11,4370,170.354049682617,-1.28100001811981,,6.50222259573638e-006,199.804992675781,2.42814309895039e-005,199.804992675781,7.08911618217826e-006,199.804992675781,,,9.88380127994453e-008,1.20083166833863e-007,1.11715986228504e-007,,50,0.00650222259573638,0.0242814309895039,0.00708911618217826,
,31180876.58,4370,168.40470123291,-1.28100001811981,,6.43730919808149e-006,199.804992675781,2.42802854627371e-005,199.804992675781,7.04806802794337e-006,199.804992675781,,,1.03408546188172e-007,1.07802664258911e-007,1.1214826256749e-007,,50,0.00643730919808149,0.0242802854627371,0.00704806802794337,
,31180932.73,4370,166.547393798828,-1.28100001811981,,6.41134386882186e-006,199.804992675781,2.42384737357497e-005,199.804992675781,6.98582752607763e-006,199.804992675781,,,1.07152694961361e-007,1.05322899481295e-007,1.02601580772864e-007,,50,0.00641134386882186,0.0242384737357497,0.00698582752607763,
,31180991.16,4370,164.590347290039,-1.28100001811981,,6.33096585050225e-006,199.804992675781,2.41955164819956e-005,199.804992675781,6.93809707649052e-006,199.804992675781,,,9.64107641897141e-008,1.20869812267293e-007,9.58799997245115e-008,,50,0.00633096585050225,0.0241955164819956,0.00693809707649052,
,31181049.55,4370,162.642700195313,-1.28100001811981,,6.28399909473955e-006,199.804992675781,2.41920799016952e-005,199.804992675781,6.89609427936375e-006,199.804992675781,,,1.07477949389799e-007,1.21839395843942e-007,1.16368357063111e-007,,50,0.00628399909473956,0.0241920799016953,0.00689609427936375,
,31181108.08,4370,160.687797546387,-1.28100001811981,,6.22882258147001e-006,199.804992675781,2.41842521354556e-005,199.804992675781,6.81476161815226e-006,199.804992675781,,,1.04559098326384e-007,1.12919638886808e-007,1.11434253895598e-007,,50,0.00622882258147001,0.0241842521354556,0.00681476161815226,
,31181166.52,4370,158.742095947266,-1.28100001811981,,6.17631921544671e-006,199.804992675781,2.41769971325993e-005,199.804992675781,6.7622580844909e-006,199.804992675781,,,1.25064669759495e-007,1.15339275770685e-007,1.28044208647923e-007,,50,0.00617631921544671,0.0241769971325994,0.0067622580844909,
,31181225.05,4370,156.790397644043,-1.28100001811981,,6.11426962539554e-006,199.804992675781,2.4126784875989e-005,199.804992675781,6.69333530589938e-006,199.804992675781,,,1.19295486707804e-007,1.22099994714441e-007,9.65498001485336e-008,,50,0.00611426962539554,0.024126784875989,0.00669333530589938,
,31181283.42,4370,154.838798522949,-1.28100001811981,,6.0644390527159e-006,199.804992675781,2.41302214562893e-005,199.804992675781,6.65476911701262e-006,199.804992675781,,,1.29066982246716e-007,1.25813401750122e-007,1.20229816938204e-007,,50,0.0060644390527159,0.0241302214562893,0.00665476911701262,
,31181342.13,4370,152.890647888184,-1.28100001811981,,6.02358181029558e-006,199.804992675781,2.4056716747582e-005,199.804992675781,6.58412805758416e-006,199.804992675781,,,1.05215065216935e-007,1.13359944830578e-007,1.0874233346526e-007,,50,0.00602358181029558,0.024056716747582,0.00658412805758417,
,31181398.25,4370,151.022048950195,-1.28100001811981,,5.98787954077125e-006,199.804992675781,2.40519437938929e-005,199.804992675781,6.54766200110316e-006,199.804992675781,,,9.04979180255513e-008,1.10142794103248e-007,1.08594956061957e-007,,50,0.00598787954077125,0.0240519437938929,0.00654766200110316,
,31181454.36,4370,149.150451660156,-1.28100001811981,,5.92888463288546e-006,199.804992675781,2.40635899826884e-005,199.804992675781,6.45926520228385e-006,199.804992675781,,,1.18029809861619e-007,9.75435081533541e-008,1.2625056385885e-007,,50,0.00592888463288546,0.0240635899826884,0.00645926520228386,
,31181511.61,4370,147.24454498291,-1.28100001811981,,5.86702598258853e-006,199.804992675781,2.40271239727735e-005,199.804992675781,6.40447071753442e-006,199.804992675781,,,1.13610463371275e-007,1.03185315705027e-007,1.07938260425767e-007,,50,0.00586702598258853,0.0240271239727736,0.00640447071753442,
,31181570.02,4370,145.29239654541,-1.28100001811981,,5.82655053585768e-006,199.804992675781,2.40107047557831e-005,199.804992675781,6.34623953141271e-006,199.804992675781,,,1.07727204425286e-007,1.10248833315953e-007,1.05991675968882e-007,,50,0.00582655053585768,0.0240107047557831,0.00634623953141272,
,31181628.52,4370,143.340049743652,-1.28100001811981,,5.74999092146754e-006,199.804992675781,2.40118501335382e-005,199.804992675781,6.3053822889924e-006,199.804992675781,,,1.11858108725557e-007,1.06929258937722e-007,1.25606180144286e-007,,50,0.00574999092146754,0.0240118501335382,0.0063053822889924,
,31181685.91,4370,141.43529510498,-1.28100001811981,,5.71963441558182e-006,199.804992675781,2.39929488673806e-005,199.804992675781,6.25020589679479e-006,199.804992675781,,,9.70769076276151e-008,1.02119150407004e-007,1.17052498920967e-007,,50,0.00571963441558182,0.0239929488673806,0.0062502058967948,
,31181744.45,4370,139.48014831543,-1.28100001811981,,5.61844578944147e-006,199.804992675781,2.39897033572197e-005,199.804992675781,6.16810947656631e-006,199.804992675781,,,1.10654947788588e-007,1.06111248625118e-007,1.13417921792106e-007,,50,0.00561844578944147,0.0239897033572197,0.00616810947656631,
,31181802.98,4370,137.527305603027,-1.28100001811981,,5.58293436653912e-006,199.804992675781,2.39387269690633e-005,199.804992675781,6.10262341797352e-006,199.804992675781,,,1.00272262088346e-007,1.21295887644392e-007,1.03996061295707e-007,,50,0.00558293436653912,0.0239387269690633,0.00610262341797352,
,31181861.44,4370,135.576049804688,-1.28100001811981,,5.55486884899437e-006,199.804992675781,2.39345267787576e-005,199.804992675781,6.04133753105998e-006,199.804992675781,,,1.29168807534666e-007,1.09872749823555e-007,1.15472326200731e-007,,50,0.00555486884899437,0.0239345267787576,0.00604133753105998,
,31181918.88,4370,133.671699523926,-1.28100001811981,,5.44298869557679e-006,199.804992675781,2.39150526002049e-005,199.804992675781,5.95599554479122e-006,199.804992675781,,,1.29710117313027e-007,1.07499781496474e-007,1.02100187919104e-007,,50,0.00544298869557679,0.0239150526002049,0.00595599554479122,
,31181976.23,4370,131.753150939941,-1.28100001811981,,5.39774022996425e-006,199.804992675781,2.39047426357865e-005,199.804992675781,5.93900345265865e-006,199.804992675781,,,1.28800212820332e-007,1.33031155564565e-007,1.24553759336489e-007,,50,0.00539774022996426,0.0239047426357865,0.00593900345265865,
,31182034.75,4370,129.800498962402,-1.28100001811981,,5.32881746999919e-006,199.804992675781,2.39007334411144e-005,199.804992675781,5.83781491033733e-006,199.804992675781,,,1.14302913025852e-007,1.14967366855161e-007,1.17229836436814e-007,,50,0.00532881746999919,0.0239007334411144,0.00583781491033733,
,31182093.36,4370,127.853500366211,-1.28100001811981,,5.27860501781106e-006,199.804992675781,2.38707583025098e-005,199.804992675781,5.78149302862585e-006,199.804992675781,,,1.03924603417449e-007,1.26415025833511e-007,9.90543608984799e-008,,50,0.00527860501781106,0.0238707583025098,0.00578149302862585,
,31182150.58,4370,125.949100494385,-1.28100001811981,,5.21731914021075e-006,199.804992675781,2.38514751940966e-005,199.804992675781,5.70187866687775e-006,199.804992675781,,,1.15507071746052e-007,9.96131960011049e-008,1.26517224916595e-007,,50,0.00521731914021075,0.0238514751940966,0.00570187866687775,
,31182209.03,4370,123.99914932251,-1.28100001811981,,5.17474357970059e-006,199.804992675781,2.3872667811811e-005,199.804992675781,5.65300267189741e-006,199.804992675781,,,1.08638367515442e-007,9.92120594507366e-008,1.22513058234142e-007,,50,0.00517474357970059,0.023872667811811,0.00565300267189741,
,31182265.30,4370,122.120597839355,-1.28100001811981,,5.08462852798402e-006,199.804992675781,2.38657946512103e-005,199.804992675781,5.54016791284084e-006,199.804992675781,,,1.02277086811387e-007,1.1348954965656e-007,1.19608496311045e-007,,50,0.00508462852798402,0.0238657946512103,0.00554016791284084,
,31182323.63,4370,120.180950164795,-1.28100001811981,,5.00596866942942e-006,199.804992675781,2.38375374302268e-005,199.804992675781,5.49530128017068e-006,199.804992675781,,,1.06711503550125e-007,8.31837917716476e-008,9.79971272437001e-008,,50,0.00500596866942942,0.0238375374302268,0.00549530128017068,
,31182428.42,4370,119.64134979248,-1.28100001811981,,4.97542117722332e-006,199.804992675781,2.38153902813792e-005,199.804992675781,5.47029050067067e-006,199.804992675781,,,1.10849798911856e-007,1.26677185210651e-007,1.09175873679589e-007,,50,0.00497542117722332,0.0238153902813792,0.00547029050067067,
,31182485.63,4370,118.653350830078,-1.28100001811981,,4.99126773327589e-006,199.804992675781,2.38192089274526e-005,199.804992675781,5.39583102799952e-006,199.804992675781,,,1.10124161202192e-007,1.24286420203129e-007,1.20893753340136e-007,,50,0.00499126773327589,0.0238192089274526,0.00539583102799952,
,31182544.06,4370,117.67850112915,-1.28100001811981,,4.91451716050505e-006,199.804992675781,2.3857775516808e-005,199.804992675781,5.38227561861277e-006,199.804992675781,,,1.00477986434017e-007,1.09598926175653e-007,1.28864291094724e-007,,50,0.00491451716050506,0.023857775516808,0.00538227561861277,
,31182601.27,4370,116.724098205566,-1.28100001811981,,4.90668935701251e-006,199.804992675781,2.38375375792384e-005,199.804992675781,5.36337433382869e-006,199.804992675781,,,1.17955027416078e-007,1.01266230239066e-007,9.56203814544095e-008,,50,0.00490668935701251,0.0238375375792384,0.00536337433382869,
,31182658.48,4370,115.770801544189,-1.28100001811981,,4.87499632872641e-006,199.804992675781,2.38680853322148e-005,199.804992675781,5.297124478966e-006,199.804992675781,,,1.12650949197061e-007,1.00452971733057e-007,1.24146885998572e-007,,50,0.00487499632872641,0.0238680853322148,0.005297124478966,
,31182717.09,4370,114.79615020752,-1.28100001811981,,4.84864916652441e-006,199.804992675781,2.38608304038644e-005,199.804992675781,5.25111232884228e-006,199.804992675781,,,1.09423978625281e-007,1.12713011184242e-007,1.19974880991779e-007,,50,0.00484864916652441,0.0238608304038644,0.00525111232884228,
,31182775.39,4370,113.825000762939,-1.28100001811981,,4.81294681318104e-006,199.804992675781,2.38547208532691e-005,199.804992675781,5.22361949086189e-006,199.804992675781,,,1.30676036178463e-007,1.3185103171019e-007,9.92426300987356e-008,,50,0.00481294681318104,0.0238547208532691,0.00522361949086189,
,31182831.42,4370,112.890399932861,-1.28100001811981,,4.78087195195257e-006,199.804992675781,2.38243639469147e-005,199.804992675781,5.19784511066973e-006,199.804992675781,,,1.07624481374983e-007,1.17305993571008e-007,1.15064993636578e-007,,50,0.00478087195195258,0.0238243639469147,0.00519784511066973,
,31182888.70,4370,111.935001373291,-1.28100001811981,,4.74440586753189e-006,199.804992675781,2.38325736299157e-005,199.804992675781,5.15240577049554e-006,199.804992675781,,,1.2319998184357e-007,1.14571444688499e-007,1.01813531284903e-007,,50,0.0047444058675319,0.0238325736299157,0.00515240577049553,
,31182944.80,4370,110.998249053955,-1.28100001811981,,4.68789306469261e-006,199.804992675781,2.38184455409646e-005,199.804992675781,5.13675015419722e-006,199.804992675781,,,1.10764868083763e-007,1.26474828695675e-007,1.11705530146549e-007,,50,0.00468789306469262,0.0238184455409646,0.00513675015419722,
,31183001.13,4370,110.063751220703,-1.28100001811981,,4.68502926640212e-006,199.804992675781,2.38602577149868e-005,199.804992675781,5.09780216030777e-006,199.804992675781,,,1.12761689330078e-007,9.90457791903172e-008,1.01035140551296e-007,,50,0.00468502926640213,0.0238602577149868,0.00509780216030776,
,31183059.58,4370,109.087398529053,-1.28100001811981,,4.6239342726767e-006,199.804992675781,2.38249369338155e-005,199.804992675781,5.02601552754641e-006,199.804992675781,,,1.01689616052147e-007,1.11118357692618e-007,1.20753354756859e-007,,50,0.00462393427267671,0.0238249369338155,0.00502601552754641,
,31183116.98,4370,108.133502960205,-1.28100001811981,,4.60236015729606e-006,199.804992675781,2.383963778615e-005,199.804992675781,5.03957099281252e-006,199.804992675781,,,1.11923773989271e-007,1.09900448172773e-007,1.32973169081896e-007,,50,0.00460236015729606,0.02383963778615,0.00503957099281251,
,31183174.30,4370,107.180099487305,-1.28100001811981,,4.57773121073842e-006,199.804992675781,2.38507113605738e-005,199.804992675781,4.9779031984508e-006,199.804992675781,,,1.11328989406176e-007,9.56573550207227e-008,1.31503570010749e-007,,50,0.00457773121073842,0.0238507113605738,0.0049779031984508,
,31183231.52,4370,106.224849700928,-1.28100001811981,,4.53534663654864e-006,199.804992675781,2.38833592459559e-005,199.804992675781,4.92826351895928e-006,199.804992675781,,,1.1431813389253e-007,1.03103162540641e-007,8.80273621951857e-008,,50,0.00453534663654864,0.0238833592459559,0.00492826351895928,
,31183288.80,4370,105.270153045654,-1.28100001811981,,4.4563050288707e-006,199.804992675781,2.38465108722448e-005,199.804992675781,4.93685504421592e-006,199.804992675781,,,1.00514250693732e-007,1.2022046901491e-007,1.03826386678336e-007,,50,0.0044563050288707,0.0238465108722448,0.00493685504421592,
,31183346.09,4370,104.314849853516,-1.28100001811981,,4.45305939763785e-006,199.804992675781,2.38270369172096e-005,199.804992675781,4.88969732075929e-006,199.804992675781,,,1.15507474154138e-007,1.12806660135742e-007,1.27536436081484e-007,,50,0.00445305939763784,0.0238270369172096,0.0048896973207593,
,31183402.16,4370,103.378700256348,-1.28100001811981,,4.42862139083445e-006,199.804992675781,2.38476564735174e-005,199.804992675781,4.83604831621051e-006,199.804992675781,,,1.13109472190544e-007,1.19968582764967e-007,1.20189741955508e-007,,50,0.00442862139083445,0.0238476564735174,0.00483604831621051,
,31183459.39,4370,102.425998687744,-1.28100001811981,,4.38470938242972e-006,199.804992675781,2.38577759638429e-005,199.804992675781,4.78755419142544e-006,199.804992675781,,,1.25100231462254e-007,1.07160384656116e-007,1.07971944946982e-007,,50,0.00438470938242972,0.0238577759638429,0.00478755419142544,
,31183517.73,4370,101.452800750732,-1.28100001811981,,4.30795890279114e-006,199.804992675781,2.38759134709835e-005,199.804992675781,4.77514428086578e-006,199.804992675781,,,1.26931224131808e-007,1.01201106671252e-007,1.43207673324121e-007,,50,0.00430795890279114,0.0238759134709835,0.00477514428086579,
,31183576.13,4370,100.480400085449,-1.28100001811981,,4.3203688133508e-006,199.804992675781,2.38671308755875e-005,199.804992675781,4.73676903173327e-006,199.804992675781,,,9.85809085407078e-008,1.10719216430244e-007,9.28869087804364e-008,,50,0.0043203688133508,0.0238671308755875,0.00473676903173327,
,31183634.34,4370,99.5109481811523,-1.28100001811981,,4.25259153358638e-006,199.804992675781,2.3825700096786e-005,199.804992675781,4.69075690954923e-006,199.804992675781,,,1.19188435605691e-007,1.02407224402797e-007,1.14503512909601e-007,,50,0.00425259153358638,0.023825700096786,0.00469075690954924,
,31183692.69,4370,98.5335006713867,-1.28100001811981,,4.2420908715576e-006,199.804992675781,2.38911873102188e-005,199.804992675781,4.64455383829772e-006,199.804992675781,,,1.16303973002431e-007,1.07309115167424e-007,1.11835323383154e-007,,50,0.00424209087155759,0.0238911873102188,0.00464455383829772,
,31183751.13,4370,97.5661010742188,-1.28100001811981,,4.22089857049287e-006,199.804992675781,2.38627396151423e-005,199.804992675781,4.6090423874557e-006,199.804992675781,,,9.6832520192035e-008,1.26842739781179e-007,1.06037878302527e-007,,50,0.00422089857049286,0.0238627396151423,0.0046090423874557,
,31183809.75,4370,96.5852012634277,-1.28100001811981,,4.14930291473866e-006,199.804992675781,2.38869871199131e-005,199.804992675781,4.5223639998585e-006,199.804992675781,,,1.18442499416821e-007,9.45993413235021e-008,1.09739440880833e-007,,50,0.00414930291473866,0.0238869871199131,0.0045223639998585,
,31183867.25,4370,95.630298614502,-1.28100001811981,,4.13918402977288e-006,199.804992675781,2.3891187235713e-005,199.804992675781,4.53954690136015e-006,199.804992675781,,,9.74823712537348e-008,1.16134569562831e-007,9.58078918594779e-008,,50,0.00413918402977288,0.023891187235713,0.00453954690136015,
,31183925.95,4370,94.6524505615234,-1.28100001811981,,4.11818264052272e-006,199.804992675781,2.39056973904371e-005,199.804992675781,4.49525305069983e-006,199.804992675781,,,9.32980533701882e-008,1.08785260855479e-007,1.13309287537874e-007,,50,0.00411818264052272,0.0239056973904371,0.00449525305069983,
,31183984.66,4370,93.6714477539063,-1.28100001811981,,4.06682467553765e-006,199.804992675781,2.38888961076736e-005,199.804992675781,4.46126901544631e-006,199.804992675781,,,9.51452131618754e-008,1.13951730498217e-007,1.14467233669786e-007,,50,0.00406682467553765,0.0238888961076736,0.00446126901544631,
,31184043.13,4370,92.6971969604492,-1.28100001811981,,4.03570442460477e-006,199.804992675781,2.38745769485831e-005,199.804992675781,4.39253719523549e-006,199.804992675781,,,1.06258960169802e-007,1.12846685001806e-007,1.16054821733838e-007,,50,0.00403570442460477,0.0238745769485831,0.00439253719523549,
,31184101.13,4370,91.7307014465332,-1.28100001811981,,3.99102867115289e-006,199.804992675781,2.38984423130751e-005,199.804992675781,4.38318200409413e-006,199.804992675781,,,1.29007813114069e-007,1.01625114968828e-007,9.42379618463527e-008,,50,0.00399102867115289,0.0238984423130751,0.00438318200409412,
,31184158.66,4370,90.7748489379883,-1.28100001811981,,3.94482565112412e-006,199.804992675781,2.38972967118025e-005,199.804992675781,4.30165846832097e-006,199.804992675781,,,1.18871826278641e-007,1.00298505061349e-007,1.26569583470469e-007,,50,0.00394482565112412,0.0238972967118025,0.00430165846832097,
,31184217.23,4370,89.7999000549316,-1.28100001811981,,3.89194027986378e-006,199.804992675781,2.39089431241155e-005,199.804992675781,4.28027521353215e-006,199.804992675781,,,1.24586552537981e-007,1.08592908531299e-007,1.38189475465941e-007,,50,0.00389194027986377,0.0239089431241155,0.00428027521353215,
[...]
,31382768.45,4370,29.6525993347168,2999.64599609375,,1.56847679289058e-006,5000,9.79867674410343e-006,999.023010253906,1.70584428356961e-006,5000,,,4.46603932394546e-009,2.04642894315648e-008,4.48882438033716e-009,,50,0.00156847679289058,0.00979867674410343,0.0017058442835696,
,31383276.39,4370,29.1395998001099,1000.21398925781,,1.5553771215491e-006,5000,9.62577853351831e-006,999.023010253906,1.68877727352083e-006,5000,,,3.33906511937733e-009,2.49627020022814e-008,6.33721237014625e-009,,50,0.0015553771215491,0.00962577853351831,0.00168877727352083,
,31383667.67,4370,27.8394498825073,1000.21398925781,,1.51855756994337e-006,5000,9.25458874553442e-006,999.023010253906,1.64941722759977e-006,5000,,,4.47994664063715e-009,2.44362337416621e-008,4.7946088800744e-009,,50,0.00151855756994337,0.00925458874553442,0.00164941722759977,
,31384058.52,4370,26.5377998352051,1000.21398925781,,1.48073094664142e-006,5000,8.89592245221138e-006,999.023010253906,1.60952299367636e-006,5000,,,3.82215129071415e-009,2.46878367391763e-008,3.87516756571091e-009,,50,0.00148073094664142,0.00889592245221138,0.00160952299367636,
,31384451.13,4370,25.2264003753662,1000.21398925781,,1.44333162577823e-006,5000,8.56879804283381e-006,999.023010253906,1.56872094376013e-006,5000,,,4.31519701139595e-009,2.2579508021493e-008,4.97682531544009e-009,,50,0.00144333162577823,0.0085687980428338,0.00156872094376013,
,31384841.98,4370,23.9249992370605,1000.21398925781,,1.40772516839206e-006,5000,8.27649608254433e-006,999.023010253906,1.53073409339413e-006,5000,,,3.89009156637556e-009,2.2854750269347e-008,5.00063014997056e-009,,50,0.00140772516839206,0.00827649608254433,0.00153073409339413,
,31385236.91,4370,22.6066999435425,1000.21398925781,,1.37134812306613e-006,5000,7.98152200877667e-006,999.023010253906,1.49147319607437e-006,5000,,,4.51312972377795e-009,2.27195821195841e-008,5.5721104657872e-009,,50,0.00137134812306613,0.00798152200877666,0.00149147319607437,
,31385632.91,4370,21.287449836731,1000.21398925781,,1.33615364553407e-006,5000,7.70770231261849e-006,999.023010253906,1.45279209828004e-006,5000,,,3.72574540973503e-009,2.09537070939855e-008,4.5795423514912e-009,,50,0.00133615364553407,0.00770770231261849,0.00145279209828004,
,31386028.55,4370,19.9680500030518,1000.21398925781,,1.30109656834975e-006,5000,7.46408606879413e-006,999.023010253906,1.41350826015696e-006,5000,,,3.88709812750454e-009,1.99812980213979e-008,4.63894663698117e-009,,50,0.00130109656834975,0.00746408606879413,0.00141350826015696,
,31386421.80,4370,18.6561002731323,1000.21398925781,,1.26720671076328e-006,5000,7.2306267824024e-006,999.023010253906,1.37597152963281e-006,5000,,,4.3301444894661e-009,2.9266043726776e-008,4.67171660546856e-009,,50,0.00126720671076328,0.0072306267824024,0.00137597152963281,
,31386814.20,4370,17.3473997116089,1000.21398925781,,1.23204273171723e-006,5000,7.02038405463099e-006,999.023010253906,1.33941904176027e-006,5000,,,5.25933144581805e-009,2.0771896163974e-008,3.84739509891971e-009,,50,0.00123204273171723,0.007020384054631,0.00133941904176027,
,31387211.19,4370,16.0231499671936,1000.21398925781,,1.1975731048733e-006,5000,6.81762490421533e-006,999.023010253906,1.29922737134621e-006,5000,,,4.30760864964955e-009,2.28731160576822e-008,4.27272553991331e-009,,50,0.0011975731048733,0.00681762490421534,0.00129922737134621,
,31387609.33,4370,14.6976499557495,1000.21398925781,,1.1621879064478e-006,5000,6.62945247255266e-006,999.023010253906,1.26246884930879e-006,5000,,,3.85869108970754e-009,2.5499687527167e-008,5.59721126110051e-009,,50,0.0011621879064478,0.00662945247255266,0.00126246884930879,
,31388008.77,4370,13.3649501800537,1000.21398925781,,1.12878631567582e-006,5000,6.4609448146075e-006,999.023010253906,1.22476428514346e-006,5000,,,4.00304067284832e-009,2.7553315561569e-008,4.85276834032007e-009,,50,0.00112878631567582,0.0064609448146075,0.00122476428514346,
,31388406.73,4370,12.0392003059387,1000.21398925781,,1.09526269137859e-006,5000,6.30744402296841e-006,999.023010253906,1.18922649649903e-006,5000,,,4.20407208646919e-009,2.5355802941736e-008,5.30574037202574e-009,,50,0.00109526269137859,0.00630744402296841,0.00118922649649903,
,31388800.25,4370,10.7282500267029,1000.21398925781,,1.06411185115576e-006,5000,6.15581357851625e-006,999.023010253906,1.1548407911323e-006,5000,,,4.48011769312269e-009,2.06435450364019e-008,4.5919955525771e-009,,50,0.00106411185115576,0.00615581357851624,0.0011548407911323,
,31389194.39,4370,9.40980005264282,1000.21398925781,,1.03302196832374e-006,5000,6.01288995705545e-006,999.023010253906,1.11815857468173e-006,5000,,,4.27995600053738e-009,2.29583149818725e-008,5.76495644027435e-009,,50,0.00103302196832374,0.00601288995705545,0.00111815857468173,
,31389595.30,4370,8.05800008773804,1000.21398925781,,1.00050544831902e-006,5000,5.85194258019328e-006,999.023010253906,1.08468831982464e-006,5000,,,9.55280219517269e-009,2.50106677412352e-008,5.0712076062624e-009,,50,0.00100050544831902,0.00585194258019328,0.00108468831982464,
,31390013.77,4370,6.68624997138977,1000.21398925781,,9.72581822425127e-007,5000,5.66747412085533e-006,999.023010253906,1.05208027176559e-006,5000,,,4.66215491328956e-009,1.93358523927441e-008,4.89532332719461e-009,,50,0.000972581822425127,0.00566747412085533,0.00105208027176559,
,31390406.14,4370,5.39619994163513,1000.21398925781,,9.45154053624719e-007,5000,5.44390454888344e-006,999.023010253906,1.02358441799879e-006,5000,,,3.78760831747083e-009,2.37875466738409e-008,3.54977161941813e-009,,50,0.000945154053624719,0.00544390454888344,0.00102358441799879,
,31390816.13,4370,4.08065009117126,1000.21398925781,,9.20640811091289e-007,5000,5.18425088375807e-006,999.023010253906,9.97629142366349e-007,5000,,,4.31853766877653e-009,2.74286358336773e-008,4.94343554636034e-009,,50,0.000920640811091289,0.00518425088375807,0.00099762914236635,
,31391214.08,4370,2.83439993858337,1000.21398925781,,9.02032655430958e-007,5000,4.93834392167628e-006,999.023010253906,9.7605319111608e-007,5000,,,5.11223380380232e-009,2.77306280342583e-008,4.54740828572519e-009,,50,0.000902032655430958,0.00493834392167628,0.00097605319111608,
,31391791.63,4370,2.14690005779266,2000.04895019531,,8.88849023031071e-007,5000,4.86732088960707e-006,999.023010253906,9.6306796069257e-007,5000,,,4.90980038733704e-009,2.183155246728e-008,4.05500696529908e-009,,50,0.000888849023031071,0.00486732088960707,0.00096306796069257,
,31392184.86,4370,3.45274996757507,2000.04895019531,,9.07571644056589e-007,5000,5.07901515811682e-006,999.023010253906,9.83957247808575e-007,5000,,,3.96951690704804e-009,2.469256099402e-008,4.5199846966765e-009,,50,0.000907571644056588,0.00507901515811682,0.000983957247808576,
,31392578.56,4370,4.76504993438721,2000.04895019531,,9.30391176370904e-007,5000,5.33851608633995e-006,999.023010253906,1.00551798706874e-006,5000,,,4.56487363543277e-009,1.95475265897638e-008,4.51573126424421e-009,,50,0.000930391176370904,0.00533851608633995,0.00100551798706874,
,31392978.19,4370,6.09469985961914,2000.04895019531,,9.55530107021332e-007,5000,5.58545408770442e-006,999.023010253906,1.03489118162543e-006,5000,,,3.98707321766499e-009,1.98641869870762e-008,4.5593162167894e-009,,50,0.000955530107021332,0.00558545408770442,0.00103489118162543,
,31393434.17,4370,7.60045003890991,2000.04895019531,,9.85597575781867e-007,5000,5.8141783811152e-006,999.023010253906,1.06735434615985e-006,5000,,,4.08969543535959e-009,2.55761351873316e-008,4.05579961966232e-009,,50,0.000985597575781867,0.0058141783811152,0.00106735434615985,
,31393827.73,4370,8.91184997558594,2000.04895019531,,1.01522259414196e-006,5000,5.96939782612026e-006,999.023010253906,1.10233518993482e-006,5000,,,5.25743312250471e-009,2.28721421302527e-008,4.22883401162624e-009,,50,0.00101522259414196,0.00596939782612026,0.00110233518993482,
,31394218.48,4370,10.2125000953674,2000.04895019531,,1.04633529204875e-006,5000,6.11159624531865e-006,999.023010253906,1.13698791945353e-006,5000,,,4.47039107484179e-009,2.38345740185192e-008,4.73589665332662e-009,,50,0.00104633529204875,0.00611159624531865,0.00113698791945353,
,31394608.42,4370,11.5114998817444,2000.04895019531,,1.07866872567683e-006,5000,6.25814786180854e-006,999.023010253906,1.17099222959951e-006,5000,,,4.17085271475765e-009,2.26290613399588e-008,4.97283811941939e-009,,50,0.00107866872567683,0.00625814786180854,0.00117099222959951,
,31395008.75,4370,12.8456001281738,2000.04895019531,,1.11275696894154e-006,5000,6.41413079574704e-006,999.023010253906,1.20810931548476e-006,5000,,,3.83864833274973e-009,2.04532049674075e-008,5.54668401185047e-009,,50,0.00111275696894154,0.00641413079574704,0.00120810931548476,
,31395404.00,4370,14.1626496315002,2000.04895019531,,1.14548709709197e-006,5000,6.57675789669156e-006,999.023010253906,1.24479913152754e-006,5000,,,4.53788104533055e-009,2.39461793374665e-008,4.20407844174912e-009,,50,0.00114548709709197,0.00657675789669156,0.00124479913152754,
,31395800.27,4370,15.4824500083923,2000.04895019531,,1.18198618525639e-006,5000,6.7501151561737e-006,999.023010253906,1.2833276251331e-006,5000,,,3.93653859705722e-009,2.1502945804354e-008,4.84473648932741e-009,,50,0.00118198618525639,0.00675011515617371,0.0012833276251331,
,31396193.13,4370,16.792799949646,2000.04895019531,,1.21570820221677e-006,5000,6.94374767132103e-006,999.023010253906,1.32011665729806e-006,5000,,,4.59871950975527e-009,2.58359853500112e-008,4.40197585475867e-009,,50,0.00121570820221677,0.00694374767132103,0.00132011665729806,
,31396588.61,4370,18.1128492355347,2000.04895019531,,1.24901821371168e-006,5000,7.15582352131605e-006,999.023010253906,1.35846971301362e-006,5000,,,4.21646353003037e-009,2.03775012963528e-008,4.37212363423751e-009,,50,0.00124901821371168,0.00715582352131605,0.00135846971301362,
,31396987.91,4370,19.4418497085571,2000.04895019531,,1.28415922401473e-006,5000,7.37908761948347e-006,999.023010253906,1.39805872924626e-006,5000,,,4.16316938859477e-009,2.37003493034144e-008,4.19537640482082e-009,,50,0.00128415922401473,0.00737908761948347,0.00139805872924626,
,31397382.44,4370,20.7619009017944,2000.04895019531,,1.32142128422856e-006,5000,7.62572016566992e-006,999.023010253906,1.43667875323445e-006,5000,,,4.45159690095716e-009,1.96988041090931e-008,4.94642169092668e-009,,50,0.00132142128422856,0.00762572016566992,0.00143667875323445,
,31397774.28,4370,22.0630502700806,2000.04895019531,,1.35542557807639e-006,5000,7.87437707185745e-006,999.023010253906,1.47295658709481e-006,5000,,,5.16795136574489e-009,1.81083431006473e-008,4.89460466118298e-009,,50,0.00135542557807639,0.00787437707185745,0.00147295658709481,
,31398170.66,4370,23.3853998184204,2000.04895019531,,1.39190175570548e-006,5000,8.15686490386725e-006,999.023010253906,1.51379683054984e-006,5000,,,5.00429351791085e-009,2.24403726407486e-008,4.40754614412655e-009,,50,0.00139190175570548,0.00815686490386724,0.00151379683054984,
,31398563.33,4370,24.6940994262695,2000.04895019531,,1.42885859590024e-006,5000,8.45462569966912e-006,999.023010253906,1.55253135599196e-006,5000,,,5.40105496573325e-009,2.32940592261933e-008,4.80046584636408e-009,,50,0.00142885859590024,0.00845462569966912,0.00155253135599196,
,31398958.36,4370,26.011549949646,2000.04895019531,,1.46490757586434e-006,5000,8.77575669437647e-006,999.023010253906,1.59211265854538e-006,5000,,,4.50609416895012e-009,2.1247179909502e-008,4.79797303050012e-009,,50,0.00146490757586434,0.00877575669437647,0.00159211265854537,
,31399352.22,4370,27.3239002227783,2000.04895019531,,1.50244429707527e-006,5000,9.11964481696486e-006,999.023010253906,1.63155681453645e-006,5000,,,4.98613075108963e-009,2.23851818088214e-008,4.5575579262193e-009,,50,0.00150244429707527,0.00911964481696487,0.00163155681453645,
,31399749.84,4370,28.6500005722046,2000.04895019531,,1.53972157277167e-006,5000,9.48518328368664e-006,999.023010253906,1.6733658942394e-006,5000,,,4.36951250375187e-009,2.07120827503864e-008,4.67881041248888e-009,,50,0.00153972157277167,0.00948518328368664,0.0016733658942394,
,31400144.22,4370,29.9650497436523,2000.04895019531,,1.57909691333771e-006,5000,9.8787117563188e-006,999.023010253906,1.71527434140444e-006,5000,,,4.23500858271764e-009,2.35299944210265e-008,4.60064835481435e-009,,50,0.00157909691333771,0.00987871175631881,0.00171527434140444,
,31415570.00,4370,295.092651367188,90000.1484375,,,,2.6993396691978e-005,999.023010253906,,,,,,2.21771470595466e-008,,,50,,0.026993396691978,,
,31415730.25,4370,289.819549560547,90000.1484375,,,,2.68335174769163e-005,999.023010253906,,,,,,2.15868905652149e-008,,,50,,0.0268335174769163,,
,31415873.41,4370,285.041656494141,90000.1484375,,,,2.66942596063018e-005,999.023010253906,,,,,,3.79991371521368e-008,,,50,,0.0266942596063018,,
,31416014.38,4370,280.31623840332,90000.1484375,,,,2.65533216297627e-005,999.023010253906,,,,,,2.46693739399358e-008,,,50,,0.0265533216297627,,
,31416156.94,4370,275.560852050781,90000.1484375,,,,2.64230734854937e-005,999.023010253906,,,,,,1.89421209477929e-008,,,50,,0.0264230734854937,,
,31416297.84,4370,270.876098632813,90000.1484375,,,,2.62909559533e-005,999.023010253906,,,,,,2.17891450290688e-008,,,50,,0.0262909559533,,
,31416436.69,4370,266.243988037109,90000.1484375,,,,2.61615877971053e-005,999.023010253906,,,,,,1.88007975070812e-008,,,50,,0.0261615877971053,,
,31416582.23,4370,261.400588989258,90000.1484375,,,,2.60391309857368e-005,999.023010253906,,,,,,2.0229568813973e-008,,,50,,0.0260391309857368,,
,31416722.91,4370,256.710342407227,90000.1484375,,,,2.59285493940115e-005,999.023010253906,,,,,,1.91610753857787e-008,,,50,,0.0259285493940115,,
,31416865.89,4370,251.944549560547,90000.1484375,,,,2.5834308937192e-005,999.023010253906,,,,,,2.27885300843649e-008,,,50,,0.025834308937192,,
,31417006.97,4370,247.24144744873,90000.1484375,,,,2.57498836144805e-005,999.023010253906,,,,,,2.21994890971217e-008,,,50,,0.0257498836144805,,
,31417144.25,4370,242.659301757813,90000.1484375,,,,2.56609143689275e-005,999.023010253906,,,,,,2.02383960282026e-008,,,50,,0.0256609143689275,,
,31417284.16,4370,237.986251831055,90000.1484375,,,,2.55489582195878e-005,999.023010253906,,,,,,2.15909765062394e-008,,,50,,0.0255489582195878,,
,31417425.08,4370,233.307800292969,90000.1484375,,,,2.54212319850922e-005,999.023010253906,,,,,,1.83641910862008e-008,,,50,,0.0254212319850922,,
,31417565.42,4370,228.621551513672,90000.1484375,,,,2.53206929191947e-005,999.023010253906,,,,,,2.27560365220089e-008,,,50,,0.0253206929191947,,
,31417703.75,4370,224.0166015625,90000.1484375,,,,2.52129752188921e-005,999.023010253906,,,,,,2.11701831719797e-008,,,50,,0.0252129752188921,,
,31417842.70,4370,219.392700195313,90000.1484375,,,,2.51094955205917e-005,999.023010253906,,,,,,2.19358667890397e-008,,,50,,0.0251094955205917,,
,31417980.92,4370,214.788948059082,90000.1484375,,,,2.50020055100322e-005,999.023010253906,,,,,,2.3323936450328e-008,,,50,,0.0250020055100322,,
,31418117.44,4370,210.232803344727,90000.1484375,,,,2.49061615765095e-005,999.023010253906,,,,,,2.10167250972232e-008,,,50,,0.0249061615765095,,
,31418256.91,4370,205.579902648926,90000.1484375,,,,2.48222704976797e-005,999.023010253906,,,,,,2.13730723829125e-008,,,50,,0.0248222704976797,,
,31418396.58,4370,200.926803588867,90000.1484375,,,,2.47337594628334e-005,999.023010253906,,,,,,2.32166371465265e-008,,,50,,0.0247337594628334,,
,31418535.23,4370,196.30549621582,90000.1484375,,,,2.47034793719649e-005,999.023010253906,,,,,,2.1517107567991e-008,,,50,,0.0247034793719649,,
,31418678.44,4370,191.532249450684,90000.1484375,,,,2.46134791523218e-005,999.023010253906,,,,,,2.2225187446761e-008,,,50,,0.0246134791523218,,
,31418818.34,4370,186.863800048828,90000.1484375,,,,2.45391726493835e-005,999.023010253906,,,,,,2.50419825257873e-008,,,50,,0.0245391726493835,,
,31418956.88,4370,182.257049560547,90000.1484375,,,,2.44586803019047e-005,999.023010253906,,,,,,2.43792450386471e-008,,,50,,0.0244586803019047,,
,31419094.56,4370,177.66805267334,90000.1484375,,,,2.43894523009658e-005,999.023010253906,,,,,,2.03886959799926e-008,,,50,,0.0243894523009658,,
,31419235.36,4370,172.957801818848,90000.1484375,,,,2.43146875873208e-005,999.023010253906,,,,,,1.82010629644669e-008,,,50,,0.0243146875873208,,
,31419375.11,4370,168.316551208496,90000.1484375,,,,2.42555784061551e-005,999.023010253906,,,,,,2.25261365334521e-008,,,50,,0.0242555784061551,,
,31419512.39,4370,163.740653991699,90000.1484375,,,,2.41993330419064e-005,999.023010253906,,,,,,2.60465683635675e-008,,,50,,0.0241993330419064,,
,31419649.55,4370,159.156303405762,90000.1484375,,,,2.41495026275516e-005,999.023010253906,,,,,,2.13362368592758e-008,,,50,,0.0241495026275516,,
,31419787.81,4370,154.558296203613,90000.1484375,,,,2.40976866334677e-005,999.023010253906,,,,,,1.94385837846005e-008,,,50,,0.0240976866334677,,
,31419926.00,4370,149.951103210449,90000.1484375,,,,2.40504145622253e-005,999.023010253906,,,,,,1.90577159944231e-008,,,50,,0.0240504145622253,,
,31420067.63,4370,145.231903076172,90000.1484375,,,,2.40055480971932e-005,999.023010253906,,,,,,2.5492796762309e-008,,,50,,0.0240055480971932,,
,31420204.97,4370,140.657600402832,90000.1484375,,,,2.39633923396468e-005,999.023010253906,,,,,,2.1168131867048e-008,,,50,,0.0239633923396468,,
,31420344.58,4370,136.003105163574,90000.1484375,,,,2.39268869161606e-005,999.023010253906,,,,,,2.13399550316218e-008,,,50,,0.0239268869161606,,
,31420484.27,4370,131.346496582031,90000.1484375,,,,2.3898554071784e-005,999.023010253906,,,,,,2.00757423986432e-008,,,50,,0.023898554071784,,
,31420623.08,4370,126.72269821167,90000.1484375,,,,2.38730851560831e-005,999.023010253906,,,,,,1.91212632792643e-008,,,50,,0.0238730851560831,,
,31420760.20,4370,122.140598297119,90000.1484375,,,,2.38622790202498e-005,999.023010253906,,,,,,1.72557637439066e-008,,,50,,0.0238622790202498,,
,31420900.94,4370,117.451049804688,90000.1484375,,,,2.3851091042161e-005,999.023010253906,,,,,,2.8846154355618e-008,,,50,,0.023851091042161,,
,31421039.06,4370,112.843448638916,90000.1484375,,,,2.38431105390191e-005,999.023010253906,,,,,,2.17183671398846e-008,,,50,,0.0238431105390191,,
,31421180.67,4370,108.138000488281,90000.1484375,,,,2.385273296386e-005,999.023010253906,,,,,,2.37455845304209e-008,,,50,,0.02385273296386,,
,31421322.52,4370,103.402847290039,90000.1484375,,,,2.38767890259624e-005,999.023010253906,,,,,,2.11376850276631e-008,,,50,,0.0238767890259624,,
,31421468.20,4370,98.5523490905762,90000.1484375,,,,2.38974085077643e-005,999.023010253906,,,,,,1.89079787427052e-008,,,50,,0.0238974085077643,,
,31421612.42,4370,93.7354507446289,90000.1484375,,,,2.39400992169976e-005,999.023010253906,,,,,,2.69152936340534e-008,,,50,,0.0239400992169976,,
,31421758.39,4370,88.8754501342773,90000.1484375,,,,2.39647287875414e-005,999.023010253906,,,,,,1.89725484786834e-008,,,50,,0.0239647287875414,,
,31421905.39,4370,83.9743003845215,90000.1484375,,,,2.39792389795184e-005,999.023010253906,,,,,,2.67539232456635e-008,,,50,,0.0239792389795184,,
,31422046.52,4370,79.2657012939453,90000.1484375,,,,2.39392590522766e-005,999.023010253906,,,,,,2.38231296401202e-008,,,50,,0.0239392590522766,,
,31422193.44,4370,74.3461532592773,90000.1484375,,,,2.38013751804829e-005,999.023010253906,,,,,,2.59066955878717e-008,,,50,,0.0238013751804829,,
,31422341.50,4370,69.4602508544922,90000.1484375,,,,2.34957849606872e-005,999.023010253906,,,,,,2.36349252219197e-008,,,50,,0.0234957849606872,,
,31422489.56,4370,64.5274505615234,90000.1484375,,,,2.29191249236464e-005,999.023010253906,,,,,,2.4192682805991e-008,,,50,,0.0229191249236465,,
,31422632.25,4370,59.7306499481201,90000.1484375,,,,2.20302323251963e-005,999.023010253906,,,,,,2.62798626020086e-008,,,50,,0.0220302323251963,,
,31422782.42,4370,54.7439002990723,90000.1484375,,,,2.06998884677887e-005,999.023010253906,,,,,,2.67939012807523e-008,,,50,,0.0206998884677887,,
,31422930.30,4370,49.9201488494873,90000.1484375,,,,1.89859457314014e-005,999.023010253906,,,,,,3.16140483911795e-008,,,50,,0.0189859457314014,,